Workbook

Sheet Dashboard
B2: Nagapattinam Field Calls — Live Tracker
B3: Update the 'Call Tracker' sheet as you close each call. Every number on this page recalculates automatically.
B5: SETTINGS (edit the yellow cells)
B6: Base location (pincode) | D6: 609703
B7: Conveyance rate (₹ per km) | D7: 5
B8: Report date | D8: =TODAY() -> 46223
B10: OVERVIEW
B11: TOTAL CALLS | F11: COMPLETED | J11: INCOMPLETE
B12: =COUNTA('Call Tracker'!D3:D55) -> 53 | F12: =COUNTIF('Call Tracker'!L3:L55,"Completed") -> 1 | J12: =COUNTIF('Call Tracker'!L3:L55,"Incomplete") -> 0
B15: NOT STARTED | F15: DISTANCE (KM) | J15: CONVEYANCE (₹)
B16: =COUNTIF('Call Tracker'!L3:L55,"Not Started") -> 52 | F16: =ROUND(SUM('Call Tracker'!M3:M55),1) -> 58 | J16: =ROUND(SUM('Call Tracker'!N3:N55),0) -> 290
B19: Overall completion | D19: =COUNTIF('Call Tracker'!L3:L55,"Completed")/COUNTA('Call Tracker'!D3:D55) -> 0.018867925 | F19: =REPT("█",ROUND(D19*40,0))&REPT("░",40-ROUND(D19*40,0)) -> █░░░░░░░░░░░░░░░░░░░░░░░░░░░░░░░░░░░░░░░
B22: BLOCK BREAKDOWN | G22: CATEGORY BREAKDOWN
B23: Block | C23: Total | D23: Completed | E23: % Done | G23: Category | H23: Total | I23: Completed | J23: Incomplete | K23: Not Started
B24: Keezhaiyur | C24: =COUNTIF('Call Tracker'!C3:C55,"Keezhaiyur") -> 4 | D24: =COUNTIFS('Call Tracker'!C3:C55,"Keezhaiyur",'Call Tracker'!L3:L55,"Completed") -> 0 | E24: =IFERROR(D24/C24,0) -> 0 | G24: GOOGLE FORM - AI | H24: =COUNTIF('Call Tracker'!F3:F55,"GOOGLE FORM - AI") -> 29 | I24: =COUNTIFS('Call Tracker'!F3:F55,"GOOGLE FORM - AI",'Call Tracker'!L3:L55,"Completed") -> 0 | J24: =COUNTIFS('Call Tracker'!F3:F55,"GOOGLE FORM - AI",'Call Tracker'!L3:L55,"Incomplete") -> 0 | K24: =COUNTIFS('Call Tracker'!F3:F55,"GOOGLE FORM - AI",'Call Tracker'!L3:L55,"Not Started") -> 29
B25: Nagapattinam | C25: =COUNTIF('Call Tracker'!C3:C55,"Nagapattinam") -> 13 | D25: =COUNTIFS('Call Tracker'!C3:C55,"Nagapattinam",'Call Tracker'!L3:L55,"Completed") -> 1 | E25: =IFERROR(D25/C25,0) -> 0.076923077 | G25: TICKETING TOOL TICKET | H25: =COUNTIF('Call Tracker'!F3:F55,"TICKETING TOOL TICKET") -> 16 | I25: =COUNTIFS('Call Tracker'!F3:F55,"TICKETING TOOL TICKET",'Call Tracker'!L3:L55,"Completed") -> 0 | J25: =COUNTIFS('Call Tracker'!F3:F55,"TICKETING TOOL TICKET",'Call Tracker'!L3:L55,"Incomplete") -> 0 | K25: =COUNTIFS('Call Tracker'!F3:F55,"TICKETING TOOL TICKET",'Call Tracker'!L3:L55,"Not Started") -> 16
B26: Kelvelur | C26: =COUNTIF('Call Tracker'!C3:C55,"Kelvelur") -> 7 | D26: =COUNTIFS('Call Tracker'!C3:C55,"Kelvelur",'Call Tracker'!L3:L55,"Completed") -> 0 | E26: =IFERROR(D26/C26,0) -> 0 | G26: HELPLINE TICKET | H26: =COUNTIF('Call Tracker'!F3:F55,"HELPLINE TICKET") -> 5 | I26: =COUNTIFS('Call Tracker'!F3:F55,"HELPLINE TICKET",'Call Tracker'!L3:L55,"Completed") -> 1 | J26: =COUNTIFS('Call Tracker'!F3:F55,"HELPLINE TICKET",'Call Tracker'!L3:L55,"Incomplete") -> 0 | K26: =COUNTIFS('Call Tracker'!F3:F55,"HELPLINE TICKET",'Call Tracker'!L3:L55,"Not Started") -> 4
B27: Thirumarugal | C27: =COUNTIF('Call Tracker'!C3:C55,"Thirumarugal") -> 11 | D27: =COUNTIFS('Call Tracker'!C3:C55,"Thirumarugal",'Call Tracker'!L3:L55,"Completed") -> 0 | E27: =IFERROR(D27/C27,0) -> 0 | G27: KS SMART | H27: =COUNTIF('Call Tracker'!F3:F55,"KS SMART") -> 2 | I27: =COUNTIFS('Call Tracker'!F3:F55,"KS SMART",'Call Tracker'!L3:L55,"Completed") -> 0 | J27: =COUNTIFS('Call Tracker'!F3:F55,"KS SMART",'Call Tracker'!L3:L55,"Incomplete") -> 0 | K27: =COUNTIFS('Call Tracker'!F3:F55,"KS SMART",'Call Tracker'!L3:L55,"Not Started") -> 2
B28: Thalainayar | C28: =COUNTIF('Call Tracker'!C3:C55,"Thalainayar") -> 7 | D28: =COUNTIFS('Call Tracker'!C3:C55,"Thalainayar",'Call Tracker'!L3:L55,"Completed") -> 0 | E28: =IFERROR(D28/C28,0) -> 0 | G28: Ticketing Tool | H28: =COUNTIF('Call Tracker'!F3:F55,"Ticketing Tool") -> 1 | I28: =COUNTIFS('Call Tracker'!F3:F55,"Ticketing Tool",'Call Tracker'!L3:L55,"Completed") -> 0 | J28: =COUNTIFS('Call Tracker'!F3:F55,"Ticketing Tool",'Call Tracker'!L3:L55,"Incomplete") -> 0 | K28: =COUNTIFS('Call Tracker'!F3:F55,"Ticketing Tool",'Call Tracker'!L3:L55,"Not Started") -> 1
B29: Vedaranyam | C29: =COUNTIF('Call Tracker'!C3:C55,"Vedaranyam") -> 11 | D29: =COUNTIFS('Call Tracker'!C3:C55,"Vedaranyam",'Call Tracker'!L3:L55,"Completed") -> 0 | E29: =IFERROR(D29/C29,0) -> 0

Sheet Call Tracker
A1: Nagapattinam Field Calls — Closure Tracker (53 calls, oldest first)
A2: # | B2: UDISE | C2: Block | D2: School Name | E2: Issue / Description | F2: Category | G2: Ai Name | H2: Contact No. | I2: 611001 Zone | J2: Ticket Raised On | K2: Age (Days) | L2: Status | M2: Distance from Base (km) | N2: Conveyance Cost (₹) | O2: Date Closed | P2: If Incomplete — Reason | Q2: If Completed — Action Taken | R2: Materials / Spares Used | S2: Visited By
A3: 1 | B3: 33190400501 | C3: Keezhaiyur | D3: PUMS VILUNTHAMAVADI WEST | E3: SYSTEM 5,8 N/W NOT CONNECTED | F3: HELPLINE TICKET | H3: 6384147212 | I3: NO | J3: 45954 | K3: =Dashboard!$D$8-J3 -> 269 | L3: Not Started | N3: =IF(L3<>"Completed","",IF(M3="","",IF(Dashboard!$D$7="","",M3*Dashboard!$D$7)))
A4: 2 | B4: 33190102201 | C4: Nagapattinam | D4: PUMS THERKKU POIGAINALLUR | E4: I/O BOX DAMAGED | F4: HELPLINE TICKET | H4: 6382800142 | I4: YES | J4: 46000 | K4: =Dashboard!$D$8-J4 -> 223 | L4: Completed | M4: 58 | N4: =IF(L4<>"Completed","",IF(M4="","",IF(Dashboard!$D$7="","",M4*Dashboard!$D$7))) -> 290 | O4: 46219 | Q4: Cable grimped again at switch end | R4: Rj45 Jack | S4: Shameer
A5: 3 | B5: 33190300901 | C5: Kelvelur | D5: PUMS KURUMANANGUDI | E5: IO BOX PROBLEM | F5: TICKETING TOOL TICKET | H5: 8608350855 | I5: NO | J5: 46004 | K5: =Dashboard!$D$8-J5 -> 219 | L5: Not Started | N5: =IF(L5<>"Completed","",IF(M5="","",IF(Dashboard!$D$7="","",M5*Dashboard!$D$7)))
A6: 4 | B6: 33190301001 | C6: Kelvelur | D6: PUMS ATHIPULIYUR | E6: IO box problem | F6: TICKETING TOOL TICKET | H6: 8838168341 | I6: NO | J6: 46004 | K6: =Dashboard!$D$8-J6 -> 219 | L6: Not Started | N6: =IF(L6<>"Completed","",IF(M6="","",IF(Dashboard!$D$7="","",M6*Dashboard!$D$7)))
A7: 5 | B7: 33190202401 | C7: Thirumarugal | D7: PUMS ATHALAIYUR | E7: D-Link to system lan cable not connected | F7: TICKETING TOOL TICKET | G7: Ranjitha | H7: 8438031294 | I7: NO | J7: 46007 | K7: =Dashboard!$D$8-J7 -> 216 | L7: Not Started | N7: =IF(L7<>"Completed","",IF(M7="","",IF(Dashboard!$D$7="","",M7*Dashboard!$D$7))) | U7: Ranjitha
A8: 6 | B8: 33190503301 | C8: Thalainayar | D8: GHSS VELLAPALLAM | E8: UNABLE TO CONNECT INTERNET | F8: TICKETING TOOL TICKET | H8: 8668144131 | I8: NO | J8: 46008 | K8: =Dashboard!$D$8-J8 -> 215 | L8: Not Started | N8: =IF(L8<>"Completed","",IF(M8="","",IF(Dashboard!$D$7="","",M8*Dashboard!$D$7)))
A9: 7 | B9: 33190301901 | C9: Kelvelur | D9: PUMS VADAKKALATHUR | E9: 1 SYSTEM I/O PORT ISSUE | F9: HELPLINE TICKET | H9: 9094788383 | I9: NO | J9: 46009 | K9: =Dashboard!$D$8-J9 -> 214 | L9: Not Started | N9: =IF(L9<>"Completed","",IF(M9="","",IF(Dashboard!$D$7="","",M9*Dashboard!$D$7)))
A10: 8 | B10: 33190500801 | C10: Thalainayar | D10: PUMS MARACHERY | E10: 6TH SYSTEM I/O BOX NOT WORKING | F10: HELPLINE TICKET | H10: 9751931094 | I10: NO | J10: 46029 | K10: =Dashboard!$D$8-J10 -> 194 | L10: Not Started | N10: =IF(L10<>"Completed","",IF(M10="","",IF(Dashboard!$D$7="","",M10*Dashboard!$D$7)))
A11: 9 | B11: 33190303103 | C11: Kelvelur | D11: PUMS KERALANTHAN | E11: Cpu and monitor current not supply | F11: TICKETING TOOL TICKET | H11: 9047151969 | I11: NO | J11: 46030 | K11: =Dashboard!$D$8-J11 -> 193 | L11: Not Started | N11: =IF(L11<>"Completed","",IF(M11="","",IF(Dashboard!$D$7="","",M11*Dashboard!$D$7)))
A12: 10 | B12: 33190601004 | C12: Vedaranyam | D12: PUMS THIRD STREET, VEDARANIYAM | E12: Cpu to I/O port not working | F12: TICKETING TOOL TICKET | H12: 8681931009 | I12: NO | J12: 46031 | K12: =Dashboard!$D$8-J12 -> 192 | L12: Not Started | N12: =IF(L12<>"Completed","",IF(M12="","",IF(Dashboard!$D$7="","",M12*Dashboard!$D$7)))
A13: 11 | B13: 33190602401 | C13: Vedaranyam | D13: PUMS,VOIMEDU WEST | E13: CPU to input output internet port not working | F13: TICKETING TOOL TICKET | H13: 9344592821 | I13: NO | J13: 46034 | K13: =Dashboard!$D$8-J13 -> 189 | L13: Not Started | N13: =IF(L13<>"Completed","",IF(M13="","",IF(Dashboard!$D$7="","",M13*Dashboard!$D$7)))
A14: 12 | B14: 33190602104 | C14: Vedaranyam | D14: PUMS THANIKOTTAGAM SOUTH | E14: CPU Input output internet port not working | F14: TICKETING TOOL TICKET | H14: 7639092040 | I14: NO | J14: 46034 | K14: =Dashboard!$D$8-J14 -> 189 | L14: Not Started | N14: =IF(L14<>"Completed","",IF(M14="","",IF(Dashboard!$D$7="","",M14*Dashboard!$D$7)))
A15: 13 | B15: 33190301601 | C15: Kelvelur | D15: PUMS KUTHUR | E15: One system has no internet connection | F15: TICKETING TOOL TICKET | H15: 9585513713 | I15: NO | J15: 46049 | K15: =Dashboard!$D$8-J15 -> 174 | L15: Not Started | N15: =IF(L15<>"Completed","",IF(M15="","",IF(Dashboard!$D$7="","",M15*Dashboard!$D$7)))
A16: 14 | B16: 33190202701 | C16: Thirumarugal | D16: PUMS-THIRUCHENKATTANGUDI | E16: HDMI CABLE DEMAGED | F16: HELPLINE TICKET | H16: 9790073694 | I16: NO | J16: 46049 | K16: =Dashboard!$D$8-J16 -> 174 | L16: Not Started | N16: =IF(L16<>"Completed","",IF(M16="","",IF(Dashboard!$D$7="","",M16*Dashboard!$D$7)))
A17: 15 | B17: 33190202301 | C17: Thirumarugal | D17: PUMS-VADAKARAI | E17: D-Link not connected | F17: TICKETING TOOL TICKET | G17: Parimala Devi | H17: 8344727441 | I17: NO | J17: 46050 | K17: =Dashboard!$D$8-J17 -> 173 | L17: Not Started | N17: =IF(L17<>"Completed","",IF(M17="","",IF(Dashboard!$D$7="","",M17*Dashboard!$D$7)))
A18: 16 | B18: 33190500701 | C18: Thalainayar | D18: PUMS THIRUVIDAIMARUTHUR | E18: UPS IO BOX | F18: TICKETING TOOL TICKET | H18: 9095286120 | I18: NO | J18: 46067 | K18: =Dashboard!$D$8-J18 -> 156 | L18: Not Started | N18: =IF(L18<>"Completed","",IF(M18="","",IF(Dashboard!$D$7="","",M18*Dashboard!$D$7)))
A19: 17 | B19: 33190203901 | C19: Thirumarugal | D19: PUMS-KANGALANCHERY | E19: WEB CAMERA NOT RECEIVED | F19: TICKETING TOOL TICKET | G19: Shanthini | H19: 7708898206 | I19: NO | J19: 46069 | K19: =Dashboard!$D$8-J19 -> 154 | L19: Not Started | N19: =IF(L19<>"Completed","",IF(M19="","",IF(Dashboard!$D$7="","",M19*Dashboard!$D$7)))
A20: 18 | B20: 33190200902 | C20: Thirumarugal | D20: PUPS-GOTHANDARAJAPURAM | E20: Lan cable one missing | F20: GOOGLE FORM - AI | H20: - | I20: NO | J20: 46084 | K20: =Dashboard!$D$8-J20 -> 139 | L20: Not Started | N20: =IF(L20<>"Completed","",IF(M20="","",IF(Dashboard!$D$7="","",M20*Dashboard!$D$7)))
A21: 19 | B21: 33190200102 | C21: Thirumarugal | D21: PUPS-GANAPATHIPURAM | E21: UPS LAN cable not received and Internet connection not available | F21: GOOGLE FORM - AI | H21: - | I21: NO | J21: 46084 | K21: =Dashboard!$D$8-J21 -> 139 | L21: Not Started | N21: =IF(L21<>"Completed","",IF(M21="","",IF(Dashboard!$D$7="","",M21*Dashboard!$D$7)))
A22: 20 | B22: 33190102601 | C22: Nagapattinam | D22: PUPS ALANGUDI | E22: Incomplete installation | F22: GOOGLE FORM - AI | H22: - | I22: YES | J22: 46084 | K22: =Dashboard!$D$8-J22 -> 139 | L22: Not Started | N22: =IF(L22<>"Completed","",IF(M22="","",IF(Dashboard!$D$7="","",M22*Dashboard!$D$7)))
A23: 21 | B23: 33190102303 | C23: Nagapattinam | D23: GHS,VADAVOOR | E23: Incomplete installation | F23: GOOGLE FORM - AI | H23: - | I23: YES | J23: 46084 | K23: =Dashboard!$D$8-J23 -> 139 | L23: Not Started | N23: =IF(L23<>"Completed","",IF(M23="","",IF(Dashboard!$D$7="","",M23*Dashboard!$D$7)))
A24: 22 | B24: 33190101801 | C24: Nagapattinam | D24: PUPS PUDUCHERY | E24: Incomplete installation | F24: GOOGLE FORM - AI | H24: - | I24: YES | J24: 46084 | K24: =Dashboard!$D$8-J24 -> 139 | L24: Not Started | N24: =IF(L24<>"Completed","",IF(M24="","",IF(Dashboard!$D$7="","",M24*Dashboard!$D$7)))
A25: 23 | B25: 33190203602 | C25: Thirumarugal | D25: PUPS - VICHUR | E25: UPS LAN cable not received | F25: GOOGLE FORM - AI | H25: - | I25: NO | J25: 46084 | K25: =Dashboard!$D$8-J25 -> 139 | L25: Not Started | N25: =IF(L25<>"Completed","",IF(M25="","",IF(Dashboard!$D$7="","",M25*Dashboard!$D$7)))
A26: 24 | B26: 33190400901 | C26: Keezhaiyur | D26: PUMS THATHANTHIRUVASAL | E26: TWO SYSTEM TABLE NOT ASSEMBLED(SCREW NOT AVAILABLE) | F26: GOOGLE FORM - AI | H26: 7904144337 | I26: NO | J26: 46084 | K26: =Dashboard!$D$8-J26 -> 139 | L26: Not Started | N26: =IF(L26<>"Completed","",IF(M26="","",IF(Dashboard!$D$7="","",M26*Dashboard!$D$7)))
A27: 25 | B27: 33190401005 | C27: Keezhaiyur | D27: PUPS SALLIKULAM | E27: NO POWER CONNECTION IN 9U RACK,UPS NOT WORKING,ELECTRICAL WORK WAS INCOMPLETED. | F27: GOOGLE FORM - AI | H27: - | I27: NO | J27: 46084 | K27: =Dashboard!$D$8-J27 -> 139 | L27: Not Started | N27: =IF(L27<>"Completed","",IF(M27="","",IF(Dashboard!$D$7="","",M27*Dashboard!$D$7)))
A28: 26 | B28: 33190401301 | C28: Keezhaiyur | D28: GHSS PALAKKURICHI | E28: Ups not received. | F28: GOOGLE FORM - AI | H28: - | I28: NO | J28: 46084 | K28: =Dashboard!$D$8-J28 -> 139 | L28: Not Started | N28: =IF(L28<>"Completed","",IF(M28="","",IF(Dashboard!$D$7="","",M28*Dashboard!$D$7)))
A29: 27 | B29: 33190101502 | C29: Nagapattinam | D29: PUPS PERIYANARIYANGUDI | E29: Incomplete installation | F29: GOOGLE FORM - AI | H29: - | I29: YES | J29: 46084 | K29: =Dashboard!$D$8-J29 -> 139 | L29: Not Started | N29: =IF(L29<>"Completed","",IF(M29="","",IF(Dashboard!$D$7="","",M29*Dashboard!$D$7)))
A30: 28 | B30: 33190501302 | C30: Thalainayar | D30: PUPS AYYOR | E30: Ups is power back issue, because of down our smart class room. | F30: GOOGLE FORM - AI | H30: - | I30: NO | J30: 46084 | K30: =Dashboard!$D$8-J30 -> 139 | L30: Not Started | N30: =IF(L30<>"Completed","",IF(M30="","",IF(Dashboard!$D$7="","",M30*Dashboard!$D$7)))
A31: 29 | B31: 33190503304 | C31: Thalainayar | D31: PUPS VANAVANMAHADEVI WEST | E31: IO box (D-Link) patch cord not Attached | F31: GOOGLE FORM - AI | H31: - | I31: NO | J31: 46084 | K31: =Dashboard!$D$8-J31 -> 139 | L31: Not Started | N31: =IF(L31<>"Completed","",IF(M31="","",IF(Dashboard!$D$7="","",M31*Dashboard!$D$7)))
... A50: 48 | B50: 33190502401 | C50: Thalainayar | D50: PUMS PRINJUMOOLAI | E50: network problem | F50: TICKETING TOOL TICKET | H50: 9344439540 | I50: NO | J50: 46090 | K50: =Dashboard!$D$8-J50 -> 133 | L50: Not Started | N50: =IF(L50<>"Completed","",IF(M50="","",IF(Dashboard!$D$7="","",M50*Dashboard!$D$7)))
A51: 49 | B51: 33190203302 | C51: Thirumarugal | D51: PUMS PORAKUDI | E51: CPU I/O Point | F51: TICKETING TOOL TICKET | G51: Semmalar | H51: 9597649440 | I51: NO | J51: 46094 | K51: =Dashboard!$D$8-J51 -> 129 | L51: Not Started | N51: =IF(L51<>"Completed","",IF(M51="","",IF(Dashboard!$D$7="","",M51*Dashboard!$D$7)))
A52: 50 | B52: 33190103139 | C52: Nagapattinam | D52: MPS KOTTAIMEDU STREET | E52: 1.MERAKI ROUTER 2.D-LINK 8PORT SWITCH 3.IP CAMERA 4.WEBCAMERA NOT DELIVERED | F52: TICKETING TOOL TICKET | H52: - | I52: YES | J52: 46107 | K52: =Dashboard!$D$8-J52 -> 116 | L52: Not Started | N52: =IF(L52<>"Completed","",IF(M52="","",IF(Dashboard!$D$7="","",M52*Dashboard!$D$7)))
A53: 51 | B53: 33190204101 | C53: Thirumarugal | D53: PUPS - VIRKUDI | E53: power supply issue | F53: Ticketing Tool | G53: Shanthini | H53: 7708898206 | I53: NO | J53: 46181.67 | K53: =Dashboard!$D$8-J53 -> 41.329861 | L53: Not Started | N53: =IF(L53<>"Completed","",IF(M53="","",IF(Dashboard!$D$7="","",M53*Dashboard!$D$7)))
A54: 52 | B54: 33190204001 | C54: Thirumarugal | D54: PUPS - VAZKUDI | E54: DUE TO THE IP CAMERA BEING POSITIONED DOWNWARD,THE CLASSROOM IS NOT VISIBLE.ONLY THE FLOOR TILES CAN BESEEN. | F54: KS SMART | G54: Shanthini | H54: 7708898206 | I54: NO | J54: 46189.637 | K54: =Dashboard!$D$8-J54 -> 33.3625 | L54: Not Started | N54: =IF(L54<>"Completed","",IF(M54="","",IF(Dashboard!$D$7="","",M54*Dashboard!$D$7)))
A55: 53 | B55: 33190203801 | C55: Thirumarugal | D55: PUPS RARANTHIMANGALAM | E55: DUE TO THE IP CAMERA BEING POSITIONED DOWNWARD,THE CLASSROOM IS NOT VISIBLE.ONLY THE FLOOR TILES CAN BESEEN. | F55: KS SMART | G55: Shanthini | H55: 7708898206 | I55: NO | J55: 46189.642 | K55: =Dashboard!$D$8-J55 -> 33.357639 | L55: Not Started | N55: =IF(L55<>"Completed","",IF(M55="","",IF(Dashboard!$D$7="","",M55*Dashboard!$D$7)))
A57: Legend:
A58: Columns are grouped by workflow: identify the call (A-J) → decide & log (Status, Distance, Conveyance, Date Closed) → notes (Reason / Action Taken / Materials / Visited By) at the end.
A59: Yellow cell = your daily input (Distance). Blue text = free-text fields you fill in.
...
